<?xml version="1.0" ?>
<!-- =================================================================================== -->
<!-- |    This document was autogenerated by xacro from my_robot.xacro                 | -->
<!-- |    EDITING THIS FILE BY HAND IS NOT RECOMMENDED                                 | -->
<!-- =================================================================================== -->
<robot name="my_robot" xmlns:xacro="http://www.ros.org/wiki/xacro">
  <link name="base">
    <visual>
      <geometry>
        <box size="0.07 0.06 0.04"/>
      </geometry>
      <origin rpy="0 0 0" xyz="0 0 0"/>
    </visual>
  </link>
  <link name="arm">
    <visual>
      <geometry>
        <box size="0.26 0.01 0.01"/>
      </geometry>
      <origin rpy="0 0 0" xyz="0 0 0"/>
    </visual>
  </link>
  <link name="mount">
    <visual>
      <geometry>
        <box size="0.05 0.061 0.07"/>
      </geometry>
      <origin xyz="0 0 0"/>
    </visual>
  </link>
  <link name="end_effector_1">
    <visual>
      <geometry>
        <box size="0.207 0.01 0.01"/>
      </geometry>
      <origin xyz="0 0 0"/>
    </visual>
  </link>
  <link name="end_effector_2">
    <visual>
      <geometry>
        <box size="0.01 0.01 0.08"/>
      </geometry>
      <origin xyz="0 0 0"/>
    </visual>
  </link>
  <joint name="base_to_arm" type="prismatic">
    <parent link="base"/>
    <child link="arm"/>
    <axis xyz="1 0 0"/>
    <limit effort="1" lower="0" upper="0.16" velocity="1"/>
    <origin xyz="-0.067 -0.035 -0.015"/>
  </joint>
  <joint name="arm_to_mount" type="fixed">
    <parent link="arm"/>
    <child link="mount"/>
    <origin xyz="0.155 0.02 0"/>
  </joint>
  <joint name="mount_to_end_effector_1" type="revolute">
    <parent link="mount"/>
    <child link="end_effector_1"/>
    <axis xyz="1 0 0"/>
    <limit effort="1" lower="-1.58" upper="0" velocity="1"/>
    <origin xyz="0.1285 0.012 -0.008"/>
  </joint>
  <joint name="end_effector_1_to_end_effector_2" type="fixed">
    <parent link="end_effector_1"/>
    <child link="end_effector_2"/>
    <origin xyz="0.0985 0 0.035"/>
  </joint>
</robot>

